Workbook

Sheet README
A1: Plantilla de Quiniela – Mundial 2026 (Fase de Grupos)
A3: Incluye hoja DASHBOARD con resumen de avance, clasificados directos y mejores terceros (Top 8).
A4: POSICIONES: Verde = 1°-2°; Amarillo = 3° clasificado; Rojo = eliminado.
A5: PARTIDOS protegido (solo GL_Real, GV_Real y Jugado). Contraseña: quiniela.

Sheet CONFIG
B3: Configuración
B5: Puntos por marcador exacto | C5: 3
B6: Puntos por acertar resultado (G/E/P) | C6: 1
B8: Zona horaria usada en PARTIDOS | C8: Guatemala (UTC-6)
B10: Participantes
B11: Jugador 1
B12: Jugador 2
B13: Jugador 3
B14: Jugador 4
B15: Jugador 5
B16: Jugador 6
B17: Jugador 7
B18: Jugador 8
B19: Jugador 9
B20: Jugador 10
B21: Jugador 11
... B40: Jugador 30

Sheet PARTIDOS
A1: MatchID | B1: Fecha | C1: Hora | D1: Grupo | E1: EquipoLocal | F1: EquipoVisita | G1: Sede | H1: GL_Real | I1: GV_Real | J1: Jugado
A2: 1 | B2: 46184 | C2: 0.54166667 | D2: A | E2: Mexico | F2: South Africa | G2: Estadio Azteca, Mexico City | J2: No
A3: 2 | B3: 46184 | C3: 0.83333333 | D3: A | E3: South Korea | F3: Czechia | G3: Estadio Akron, Zapopan | J3: No
A4: 3 | B4: 46185 | C4: 0.54166667 | D4: B | E4: Canada | F4: Bosnia & Herzegovina | G4: BMO Field, Toronto | J4: No
A5: 4 | B5: 46185 | C5: 0.79166667 | D5: D | E5: USA | F5: Paraguay | G5: SoFi Stadium, Inglewood | J5: No
A6: 5 | B6: 46185 | C6: 0.91666667 | D6: D | E6: Australia | F6: Türkiye | G6: BC Place, Vancouver | J6: No
A7: 6 | B7: 46186 | C7: 0.54166667 | D7: B | E7: Qatar | F7: Switzerland | G7: Levi’s Stadium, Santa Clara | J7: No
A8: 7 | B8: 46186 | C8: 0.66666667 | D8: C | E8: Brazil | F8: Morocco | G8: MetLife Stadium, East Rutherford | J8: No
A9: 8 | B9: 46186 | C9: 0.79166667 | D9: C | E9: Haiti | F9: Scotland | G9: Gillette Stadium, Foxborough | J9: No
A10: 9 | B10: 46187 | C10: 0.45833333 | D10: E | E10: Germany | F10: Curaçao | G10: NRG Stadium, Houston | J10: No
A11: 10 | B11: 46187 | C11: 0.58333333 | D11: F | E11: Netherlands | F11: Japan | G11: AT&T Stadium, Arlington | J11: No
A12: 11 | B12: 46187 | C12: 0.70833333 | D12: E | E12: Ivory Coast | F12: Ecuador | G12: Lincoln Financial Field, Philadelphia | J12: No
A13: 12 | B13: 46187 | C13: 0.83333333 | D13: F | E13: Sweden | F13: Tunisia | G13: Estadio BBVA, Monterrey | J13: No
... A73: 72 | B73: 46200 | C73: 0.83333333 | D73: J | E73: Jordan | F73: Argentina | G73: AT&T Stadium, Arlington | J73: No

Sheet PRONOSTICOS
B7: PRONOSTICOS GENERALES
B9: Participante | C9: MatchID | D9: GL_Pron | E9: GV_Pron | F9: Puntos
F10: =IF($C10="","",IF(NOT(_xlfn.XLOOKUP($C10,tPartidos[MatchID],tPartidos[Jugado],"No")="Sí"),0,IF(AND($D10=_xlfn.XLOOKUP($C10,tPartidos[MatchID],tPartidos[GL_Real],""),$E10=_xlfn.XLOOKUP($C10,tPartidos[MatchID],tPartidos[GV_Real],"")),CONFIG!$C$5,IF(SIGN($D10-$E10)=SIGN(_xlfn.XLOOKUP($C10,tPartidos[MatchID],tPartidos[GL_Real],0)-_xlfn.XLOOKUP($C10,tPartidos[MatchID],tPartidos[GV_Real],0)),CONFIG!$C$6,0))))
F11: =IF($C11="","",IF(NOT(_xlfn.XLOOKUP($C11,tPartidos[MatchID],tPartidos[Jugado],"No")="Sí"),0,IF(AND($D11=_xlfn.XLOOKUP($C11,tPartidos[MatchID],tPartidos[GL_Real],""),$E11=_xlfn.XLOOKUP($C11,tPartidos[MatchID],tPartidos[GV_Real],"")),CONFIG!$C$5,IF(SIGN($D11-$E11)=SIGN(_xlfn.XLOOKUP($C11,tPartidos[MatchID],tPartidos[GL_Real],0)-_xlfn.XLOOKUP($C11,tPartidos[MatchID],tPartidos[GV_Real],0)),CONFIG!$C$6,0))))
F12: =IF($C12="","",IF(NOT(_xlfn.XLOOKUP($C12,tPartidos[MatchID],tPartidos[Jugado],"No")="Sí"),0,IF(AND($D12=_xlfn.XLOOKUP($C12,tPartidos[MatchID],tPartidos[GL_Real],""),$E12=_xlfn.XLOOKUP($C12,tPartidos[MatchID],tPartidos[GV_Real],"")),CONFIG!$C$5,IF(SIGN($D12-$E12)=SIGN(_xlfn.XLOOKUP($C12,tPartidos[MatchID],tPartidos[GL_Real],0)-_xlfn.XLOOKUP($C12,tPartidos[MatchID],tPartidos[GV_Real],0)),CONFIG!$C$6,0))))
F13: =IF($C13="","",IF(NOT(_xlfn.XLOOKUP($C13,tPartidos[MatchID],tPartidos[Jugado],"No")="Sí"),0,IF(AND($D13=_xlfn.XLOOKUP($C13,tPartidos[MatchID],tPartidos[GL_Real],""),$E13=_xlfn.XLOOKUP($C13,tPartidos[MatchID],tPartidos[GV_Real],"")),CONFIG!$C$5,IF(SIGN($D13-$E13)=SIGN(_xlfn.XLOOKUP($C13,tPartidos[MatchID],tPartidos[GL_Real],0)-_xlfn.XLOOKUP($C13,tPartidos[MatchID],tPartidos[GV_Real],0)),CONFIG!$C$6,0))))
F14: =IF($C14="","",IF(NOT(_xlfn.XLOOKUP($C14,tPartidos[MatchID],tPartidos[Jugado],"No")="Sí"),0,IF(AND($D14=_xlfn.XLOOKUP($C14,tPartidos[MatchID],tPartidos[GL_Real],""),$E14=_xlfn.XLOOKUP($C14,tPartidos[MatchID],tPartidos[GV_Real],"")),CONFIG!$C$5,IF(SIGN($D14-$E14)=SIGN(_xlfn.XLOOKUP($C14,tPartidos[MatchID],tPartidos[GL_Real],0)-_xlfn.XLOOKUP($C14,tPartidos[MatchID],tPartidos[GV_Real],0)),CONFIG!$C$6,0))))
F15: =IF($C15="","",IF(NOT(_xlfn.XLOOKUP($C15,tPartidos[MatchID],tPartidos[Jugado],"No")="Sí"),0,IF(AND($D15=_xlfn.XLOOKUP($C15,tPartidos[MatchID],tPartidos[GL_Real],""),$E15=_xlfn.XLOOKUP($C15,tPartidos[MatchID],tPartidos[GV_Real],"")),CONFIG!$C$5,IF(SIGN($D15-$E15)=SIGN(_xlfn.XLOOKUP($C15,tPartidos[MatchID],tPartidos[GL_Real],0)-_xlfn.XLOOKUP($C15,tPartidos[MatchID],tPartidos[GV_Real],0)),CONFIG!$C$6,0))))
F16: =IF($C16="","",IF(NOT(_xlfn.XLOOKUP($C16,tPartidos[MatchID],tPartidos[Jugado],"No")="Sí"),0,IF(AND($D16=_xlfn.XLOOKUP($C16,tPartidos[MatchID],tPartidos[GL_Real],""),$E16=_xlfn.XLOOKUP($C16,tPartidos[MatchID],tPartidos[GV_Real],"")),CONFIG!$C$5,IF(SIGN($D16-$E16)=SIGN(_xlfn.XLOOKUP($C16,tPartidos[MatchID],tPartidos[GL_Real],0)-_xlfn.XLOOKUP($C16,tPartidos[MatchID],tPartidos[GV_Real],0)),CONFIG!$C$6,0))))
F17: =IF($C17="","",IF(NOT(_xlfn.XLOOKUP($C17,tPartidos[MatchID],tPartidos[Jugado],"No")="Sí"),0,IF(AND($D17=_xlfn.XLOOKUP($C17,tPartidos[MatchID],tPartidos[GL_Real],""),$E17=_xlfn.XLOOKUP($C17,tPartidos[MatchID],tPartidos[GV_Real],"")),CONFIG!$C$5,IF(SIGN($D17-$E17)=SIGN(_xlfn.XLOOKUP($C17,tPartidos[MatchID],tPartidos[GL_Real],0)-_xlfn.XLOOKUP($C17,tPartidos[MatchID],tPartidos[GV_Real],0)),CONFIG!$C$6,0))))
F18: =IF($C18="","",IF(NOT(_xlfn.XLOOKUP($C18,tPartidos[MatchID],tPartidos[Jugado],"No")="Sí"),0,IF(AND($D18=_xlfn.XLOOKUP($C18,tPartidos[MatchID],tPartidos[GL_Real],""),$E18=_xlfn.XLOOKUP($C18,tPartidos[MatchID],tPartidos[GV_Real],"")),CONFIG!$C$5,IF(SIGN($D18-$E18)=SIGN(_xlfn.XLOOKUP($C18,tPartidos[MatchID],tPartidos[GL_Real],0)-_xlfn.XLOOKUP($C18,tPartidos[MatchID],tPartidos[GV_Real],0)),CONFIG!$C$6,0))))
F19: =IF($C19="","",IF(NOT(_xlfn.XLOOKUP($C19,tPartidos[MatchID],tPartidos[Jugado],"No")="Sí"),0,IF(AND($D19=_xlfn.XLOOKUP($C19,tPartidos[MatchID],tPartidos[GL_Real],""),$E19=_xlfn.XLOOKUP($C19,tPartidos[MatchID],tPartidos[GV_Real],"")),CONFIG!$C$5,IF(SIGN($D19-$E19)=SIGN(_xlfn.XLOOKUP($C19,tPartidos[MatchID],tPartidos[GL_Real],0)-_xlfn.XLOOKUP($C19,tPartidos[MatchID],tPartidos[GV_Real],0)),CONFIG!$C$6,0))))
F20: =IF($C20="","",IF(NOT(_xlfn.XLOOKUP($C20,tPartidos[MatchID],tPartidos[Jugado],"No")="Sí"),0,IF(AND($D20=_xlfn.XLOOKUP($C20,tPartidos[MatchID],tPartidos[GL_Real],""),$E20=_xlfn.XLOOKUP($C20,tPartidos[MatchID],tPartidos[GV_Real],"")),CONFIG!$C$5,IF(SIGN($D20-$E20)=SIGN(_xlfn.XLOOKUP($C20,tPartidos[MatchID],tPartidos[GL_Real],0)-_xlfn.XLOOKUP($C20,tPartidos[MatchID],tPartidos[GV_Real],0)),CONFIG!$C$6,0))))
F21: =IF($C21="","",IF(NOT(_xlfn.XLOOKUP($C21,tPartidos[MatchID],tPartidos[Jugado],"No")="Sí"),0,IF(AND($D21=_xlfn.XLOOKUP($C21,tPartidos[MatchID],tPartidos[GL_Real],""),$E21=_xlfn.XLOOKUP($C21,tPartidos[MatchID],tPartidos[GV_Real],"")),CONFIG!$C$5,IF(SIGN($D21-$E21)=SIGN(_xlfn.XLOOKUP($C21,tPartidos[MatchID],tPartidos[GL_Real],0)-_xlfn.XLOOKUP($C21,tPartidos[MatchID],tPartidos[GV_Real],0)),CONFIG!$C$6,0))))
... F609: =IF($C609="","",IF(NOT(_xlfn.XLOOKUP($C609,tPartidos[MatchID],tPartidos[Jugado],"No")="Sí"),0,IF(AND($D609=_xlfn.XLOOKUP($C609,tPartidos[MatchID],tPartidos[GL_Real],""),$E609=_xlfn.XLOOKUP($C609,tPartidos[MatchID],tPartidos[GV_Real],"")),CONFIG!$C$5,IF(SIGN($D609-$E609)=SIGN(_xlfn.XLOOKUP($C609,tPartidos[MatchID],tPartidos[GL_Real],0)-_xlfn.XLOOKUP($C609,tPartidos[MatchID],tPartidos[GV_Real],0)),CONFIG!$C$6,0))))

Sheet TABLA_GENERAL
B5: Ranking
B7: Participante | C7: Puntos
B8: =IF(CONFIG!B11="","",CONFIG!B11) -> Jugador 1 | C8: =IF(B8="","",SUMIFS(tPicks[Puntos],tPicks[Participante],B8)) -> 0
B9: =IF(CONFIG!B12="","",CONFIG!B12) -> Jugador 2 | C9: =IF(B9="","",SUMIFS(tPicks[Puntos],tPicks[Participante],B9)) -> 0
B10: =IF(CONFIG!B13="","",CONFIG!B13) -> Jugador 3 | C10: =IF(B10="","",SUMIFS(tPicks[Puntos],tPicks[Participante],B10)) -> 0
B11: =IF(CONFIG!B14="","",CONFIG!B14) -> Jugador 4 | C11: =IF(B11="","",SUMIFS(tPicks[Puntos],tPicks[Participante],B11)) -> 0
B12: =IF(CONFIG!B15="","",CONFIG!B15) -> Jugador 5 | C12: =IF(B12="","",SUMIFS(tPicks[Puntos],tPicks[Participante],B12)) -> 0
B13: =IF(CONFIG!B16="","",CONFIG!B16) -> Jugador 6 | C13: =IF(B13="","",SUMIFS(tPicks[Puntos],tPicks[Participante],B13)) -> 0
B14: =IF(CONFIG!B17="","",CONFIG!B17) -> Jugador 7 | C14: =IF(B14="","",SUMIFS(tPicks[Puntos],tPicks[Participante],B14)) -> 0
B15: =IF(CONFIG!B18="","",CONFIG!B18) -> Jugador 8 | C15: =IF(B15="","",SUMIFS(tPicks[Puntos],tPicks[Participante],B15)) -> 0
B16: =IF(CONFIG!B19="","",CONFIG!B19) -> Jugador 9 | C16: =IF(B16="","",SUMIFS(tPicks[Puntos],tPicks[Participante],B16)) -> 0
B17: =IF(CONFIG!B20="","",CONFIG!B20) -> Jugador 10 | C17: =IF(B17="","",SUMIFS(tPicks[Puntos],tPicks[Participante],B17)) -> 0
B18: =IF(CONFIG!B21="","",CONFIG!B21) -> Jugador 11 | C18: =IF(B18="","",SUMIFS(tPicks[Puntos],tPicks[Participante],B18)) -> 0
B19: =IF(CONFIG!B22="","",CONFIG!B22) -> Jugador 12 | C19: =IF(B19="","",SUMIFS(tPicks[Puntos],tPicks[Participante],B19)) -> 0
... B57: =IF(CONFIG!B60="","",CONFIG!B60) | C57: =IF(B57="","",SUMIFS(tPicks[Puntos],tPicks[Participante],B57))

Sheet POSICIONES
B1: Posiciones por Grupo (marcadores reales) | AF1: Grupo | AG1: Equipo | AH1: Pts | AI1: DG | AJ1: GF
B2: Colores: Verde (1°-2°), Amarillo (3° clasificado), Rojo (eliminado). | AF2: A | AG2: =$B18 -> South Africa | AH2: =$J18 -> 0 | AI2: =$I18 -> 0 | AJ2: =$G18 -> 0
AF3: B | AG3: =$B25 -> Qatar | AH3: =$J25 -> 0 | AI3: =$I25 -> 0 | AJ3: =$G25 -> 0
AF4: C | AG4: =$B32 -> Morocco | AH4: =$J32 -> 0 | AI4: =$I32 -> 0 | AJ4: =$G32 -> 0
AF5: D | AG5: =$B39 -> Türkiye | AH5: =$J39 -> 0 | AI5: =$I39 -> 0 | AJ5: =$G39 -> 0
AF6: E | AG6: =$B46 -> Germany | AH6: =$J46 -> 0 | AI6: =$I46 -> 0 | AJ6: =$G46 -> 0
AF7: F | AG7: =$B53 -> Sweden | AH7: =$J53 -> 0 | AI7: =$I53 -> 0 | AJ7: =$G53 -> 0
AF8: G | AG8: =$B60 -> Iran | AH8: =$J60 -> 0 | AI8: =$I60 -> 0 | AJ8: =$G60 -> 0
AF9: H | AG9: =$B67 -> Spain | AH9: =$J67 -> 0 | AI9: =$I67 -> 0 | AJ9: =$G67 -> 0
AF10: I | AG10: =$B74 -> Norway | AH10: =$J74 -> 0 | AI10: =$I74 -> 0 | AJ10: =$G74 -> 0
AF11: J | AG11: =$B81 -> Austria | AH11: =$J81 -> 0 | AI11: =$I81 -> 0 | AJ11: =$G81 -> 0
B14: Grupo A | N14: Mejores terceros (Top 8) | AF14: K | AG14: =$B88 -> Portugal | AH14: =$J88 -> 0 | AI14: =$I88 -> 0 | AJ14: =$G88 -> 0
B15: Equipo | C15: PJ | D15: G | E15: E | F15: P | G15: GF | H15: GC | I15: DG | J15: Pts | K15: Clasifica | N15: Pos | O15: Grupo | P15: Equipo | Q15: Pts | R15: DG | S15: GF | AF15: L | AG15: =$B95 -> Ghana | AH15: =$J95 -> 0 | AI15: =$I95 -> 0 | AJ15: =$G95 -> 0
B16: {=_xlfn.SORTBY(V16:AD19,AD16:AD19,-1,AC16:AC19,-1,AA16:AA19,-1)} -> Czechia | C16: 0 | D16: 0 | E16: 0 | F16: 0 | G16: 0 | H16: 0 | I16: 0 | J16: 0 | K16: Q | N16: 1 | O16: {=_xlfn.TAKE(_xlfn.SORTBY(CHOOSE(_xlfn.SEQUENCE(1,5),$AF$2:$AF$15,$AG$2:$AG$15,$AH$2:$AH$15,$AI$2:$AI$15,$AJ$2:$AJ$15),$AH$2:$AH$15,-1,$AI$2:$AI$15,-1,$AJ$2:$AJ$15,-1),8)} -> A | P16: South Africa | Q16: 0 | R16: 0 | S16: 0 | V16: Czechia | W16: =COUNTIFS(tPartidos[Jugado],"Sí",tPartidos[EquipoLocal],V16)+COUNTIFS(tPartidos[Jugado],"Sí",tPartidos[EquipoVisita],V16) -> 0 | X16: =SUMPRODUCT((tPartidos[Jugado]="Sí")*(tPartidos[EquipoLocal]=V16)*(tPartidos[GL_Real]>tPartidos[GV_Real]))+SUMPRODUCT((tPartidos[Jugado]="Sí")*(tPartidos[EquipoVisita]=V16)*(tPartidos[GV_Real]>tPartidos[GL_Real])) -> 0 | Y16: =SUMPRODUCT((tPartidos[Jugado]="Sí")*((tPartidos[EquipoLocal]=V16)+(tPartidos[EquipoVisita]=V16))*(tPartidos[GL_Real]=tPartidos[GV_Real])) -> 0 | Z16: =W16-X16-Y16 -> 0 | AA16: =SUMIFS(tPartidos[GL_Real],tPartidos[Jugado],"Sí",tPartidos[EquipoLocal],V16)+SUMIFS(tPartidos[GV_Real],tPartidos[Jugado],"Sí",tPartidos[EquipoVisita],V16) -> 0 | AB16: =SUMIFS(tPartidos[GV_Real],tPartidos[Jugado],"Sí",tPartidos[EquipoLocal],V16)+SUMIFS(tPartidos[GL_Real],tPartidos[Jugado],"Sí",tPartidos[EquipoVisita],V16) -> 0 | AC16: =AA16-AB16 -> 0 | AD16: =X16*3+Y16 -> 0
B17: Mexico | C17: 0 | D17: 0 | E17: 0 | F17: 0 | G17: 0 | H17: 0 | I17: 0 | J17: 0 | K17: Q | N17: 2 | O17: B | P17: Qatar | Q17: 0 | R17: 0 | S17: 0 | V17: Mexico | W17: =COUNTIFS(tPartidos[Jugado],"Sí",tPartidos[EquipoLocal],V17)+COUNTIFS(tPartidos[Jugado],"Sí",tPartidos[EquipoVisita],V17) -> 0 | X17: =SUMPRODUCT((tPartidos[Jugado]="Sí")*(tPartidos[EquipoLocal]=V17)*(tPartidos[GL_Real]>tPartidos[GV_Real]))+SUMPRODUCT((tPartidos[Jugado]="Sí")*(tPartidos[EquipoVisita]=V17)*(tPartidos[GV_Real]>tPartidos[GL_Real])) -> 0 | Y17: =SUMPRODUCT((tPartidos[Jugado]="Sí")*((tPartidos[EquipoLocal]=V17)+(tPartidos[EquipoVisita]=V17))*(tPartidos[GL_Real]=tPartidos[GV_Real])) -> 0 | Z17: =W17-X17-Y17 -> 0 | AA17: =SUMIFS(tPartidos[GL_Real],tPartidos[Jugado],"Sí",tPartidos[EquipoLocal],V17)+SUMIFS(tPartidos[GV_Real],tPartidos[Jugado],"Sí",tPartidos[EquipoVisita],V17) -> 0 | AB17: =SUMIFS(tPartidos[GV_Real],tPartidos[Jugado],"Sí",tPartidos[EquipoLocal],V17)+SUMIFS(tPartidos[GL_Real],tPartidos[Jugado],"Sí",tPartidos[EquipoVisita],V17) -> 0 | AC17: =AA17-AB17 -> 0 | AD17: =X17*3+Y17 -> 0
B18: South Africa | C18: 0 | D18: 0 | E18: 0 | F18: 0 | G18: 0 | H18: 0 | I18: 0 | J18: 0 | K18: =IF(ISNUMBER(MATCH($B18,$P$16:$P$23,0)),"3°","") -> 3° | N18: 3 | O18: C | P18: Morocco | Q18: 0 | R18: 0 | S18: 0 | V18: South Africa | W18: =COUNTIFS(tPartidos[Jugado],"Sí",tPartidos[EquipoLocal],V18)+COUNTIFS(tPartidos[Jugado],"Sí",tPartidos[EquipoVisita],V18) -> 0 | X18: =SUMPRODUCT((tPartidos[Jugado]="Sí")*(tPartidos[EquipoLocal]=V18)*(tPartidos[GL_Real]>tPartidos[GV_Real]))+SUMPRODUCT((tPartidos[Jugado]="Sí")*(tPartidos[EquipoVisita]=V18)*(tPartidos[GV_Real]>tPartidos[GL_Real])) -> 0 | Y18: =SUMPRODUCT((tPartidos[Jugado]="Sí")*((tPartidos[EquipoLocal]=V18)+(tPartidos[EquipoVisita]=V18))*(tPartidos[GL_Real]=tPartidos[GV_Real])) -> 0 | Z18: =W18-X18-Y18 -> 0 | AA18: =SUMIFS(tPartidos[GL_Real],tPartidos[Jugado],"Sí",tPartidos[EquipoLocal],V18)+SUMIFS(tPartidos[GV_Real],tPartidos[Jugado],"Sí",tPartidos[EquipoVisita],V18) -> 0 | AB18: =SUMIFS(tPartidos[GV_Real],tPartidos[Jugado],"Sí",tPartidos[EquipoLocal],V18)+SUMIFS(tPartidos[GL_Real],tPartidos[Jugado],"Sí",tPartidos[EquipoVisita],V18) -> 0 | AC18: =AA18-AB18 -> 0 | AD18: =X18*3+Y18 -> 0
B19: South Korea | C19: 0 | D19: 0 | E19: 0 | F19: 0 | G19: 0 | H19: 0 | I19: 0 | J19: 0 | N19: 4 | O19: D | P19: Türkiye | Q19: 0 | R19: 0 | S19: 0 | V19: South Korea | W19: =COUNTIFS(tPartidos[Jugado],"Sí",tPartidos[EquipoLocal],V19)+COUNTIFS(tPartidos[Jugado],"Sí",tPartidos[EquipoVisita],V19) -> 0 | X19: =SUMPRODUCT((tPartidos[Jugado]="Sí")*(tPartidos[EquipoLocal]=V19)*(tPartidos[GL_Real]>tPartidos[GV_Real]))+SUMPRODUCT((tPartidos[Jugado]="Sí")*(tPartidos[EquipoVisita]=V19)*(tPartidos[GV_Real]>tPartidos[GL_Real])) -> 0 | Y19: =SUMPRODUCT((tPartidos[Jugado]="Sí")*((tPartidos[EquipoLocal]=V19)+(tPartidos[EquipoVisita]=V19))*(tPartidos[GL_Real]=tPartidos[GV_Real])) -> 0 | Z19: =W19-X19-Y19 -> 0 | AA19: =SUMIFS(tPartidos[GL_Real],tPartidos[Jugado],"Sí",tPartidos[EquipoLocal],V19)+SUMIFS(tPartidos[GV_Real],tPartidos[Jugado],"Sí",tPartidos[EquipoVisita],V19) -> 0 | AB19: =SUMIFS(tPartidos[GV_Real],tPartidos[Jugado],"Sí",tPartidos[EquipoLocal],V19)+SUMIFS(tPartidos[GL_Real],tPartidos[Jugado],"Sí",tPartidos[EquipoVisita],V19) -> 0 | AC19: =AA19-AB19 -> 0 | AD19: =X19*3+Y19 -> 0
N20: 5 | O20: E | P20: Germany | Q20: 0 | R20: 0 | S20: 0
B21: Grupo B | N21: 6 | O21: F | P21: Sweden | Q21: 0 | R21: 0 | S21: 0
B22: Equipo | C22: PJ | D22: G | E22: E | F22: P | G22: GF | H22: GC | I22: DG | J22: Pts | K22: Clasifica | N22: 7 | O22: G | P22: Iran | Q22: 0 | R22: 0 | S22: 0
B23: {=_xlfn.SORTBY(V23:AD26,AD23:AD26,-1,AC23:AC26,-1,AA23:AA26,-1)} -> Bosnia & Herzegovina | C23: 0 | D23: 0 | E23: 0 | F23: 0 | G23: 0 | H23: 0 | I23: 0 | J23: 0 | K23: Q | N23: 8 | O23: H | P23: Spain | Q23: 0 | R23: 0 | S23: 0 | V23: Bosnia & Herzegovina | W23: =COUNTIFS(tPartidos[Jugado],"Sí",tPartidos[EquipoLocal],V23)+COUNTIFS(tPartidos[Jugado],"Sí",tPartidos[EquipoVisita],V23) -> 0 | X23: =SUMPRODUCT((tPartidos[Jugado]="Sí")*(tPartidos[EquipoLocal]=V23)*(tPartidos[GL_Real]>tPartidos[GV_Real]))+SUMPRODUCT((tPartidos[Jugado]="Sí")*(tPartidos[EquipoVisita]=V23)*(tPartidos[GV_Real]>tPartidos[GL_Real])) -> 0 | Y23: =SUMPRODUCT((tPartidos[Jugado]="Sí")*((tPartidos[EquipoLocal]=V23)+(tPartidos[EquipoVisita]=V23))*(tPartidos[GL_Real]=tPartidos[GV_Real])) -> 0 | Z23: =W23-X23-Y23 -> 0 | AA23: =SUMIFS(tPartidos[GL_Real],tPartidos[Jugado],"Sí",tPartidos[EquipoLocal],V23)+SUMIFS(tPartidos[GV_Real],tPartidos[Jugado],"Sí",tPartidos[EquipoVisita],V23) -> 0 | AB23: =SUMIFS(tPartidos[GV_Real],tPartidos[Jugado],"Sí",tPartidos[EquipoLocal],V23)+SUMIFS(tPartidos[GL_Real],tPartidos[Jugado],"Sí",tPartidos[EquipoVisita],V23) -> 0 | AC23: =AA23-AB23 -> 0 | AD23: =X23*3+Y23 -> 0
B24: Canada | C24: 0 | D24: 0 | E24: 0 | F24: 0 | G24: 0 | H24: 0 | I24: 0 | J24: 0 | K24: Q | V24: Canada | W24: =COUNTIFS(tPartidos[Jugado],"Sí",tPartidos[EquipoLocal],V24)+COUNTIFS(tPartidos[Jugado],"Sí",tPartidos[EquipoVisita],V24) -> 0 | X24: =SUMPRODUCT((tPartidos[Jugado]="Sí")*(tPartidos[EquipoLocal]=V24)*(tPartidos[GL_Real]>tPartidos[GV_Real]))+SUMPRODUCT((tPartidos[Jugado]="Sí")*(tPartidos[EquipoVisita]=V24)*(tPartidos[GV_Real]>tPartidos[GL_Real])) -> 0 | Y24: =SUMPRODUCT((tPartidos[Jugado]="Sí")*((tPartidos[EquipoLocal]=V24)+(tPartidos[EquipoVisita]=V24))*(tPartidos[GL_Real]=tPartidos[GV_Real])) -> 0 | Z24: =W24-X24-Y24 -> 0 | AA24: =SUMIFS(tPartidos[GL_Real],tPartidos[Jugado],"Sí",tPartidos[EquipoLocal],V24)+SUMIFS(tPartidos[GV_Real],tPartidos[Jugado],"Sí",tPartidos[EquipoVisita],V24) -> 0 | AB24: =SUMIFS(tPartidos[GV_Real],tPartidos[Jugado],"Sí",tPartidos[EquipoLocal],V24)+SUMIFS(tPartidos[GL_Real],tPartidos[Jugado],"Sí",tPartidos[EquipoVisita],V24) -> 0 | AC24: =AA24-AB24 -> 0 | AD24: =X24*3+Y24 -> 0
B25: Qatar | C25: 0 | D25: 0 | E25: 0 | F25: 0 | G25: 0 | H25: 0 | I25: 0 | J25: 0 | K25: =IF(ISNUMBER(MATCH($B25,$P$16:$P$23,0)),"3°","") -> 3° | V25: Qatar | W25: =COUNTIFS(tPartidos[Jugado],"Sí",tPartidos[EquipoLocal],V25)+COUNTIFS(tPartidos[Jugado],"Sí",tPartidos[EquipoVisita],V25) -> 0 | X25: =SUMPRODUCT((tPartidos[Jugado]="Sí")*(tPartidos[EquipoLocal]=V25)*(tPartidos[GL_Real]>tPartidos[GV_Real]))+SUMPRODUCT((tPartidos[Jugado]="Sí")*(tPartidos[EquipoVisita]=V25)*(tPartidos[GV_Real]>tPartidos[GL_Real])) -> 0 | Y25: =SUMPRODUCT((tPartidos[Jugado]="Sí")*((tPartidos[EquipoLocal]=V25)+(tPartidos[EquipoVisita]=V25))*(tPartidos[GL_Real]=tPartidos[GV_Real])) -> 0 | Z25: =W25-X25-Y25 -> 0 | AA25: =SUMIFS(tPartidos[GL_Real],tPartidos[Jugado],"Sí",tPartidos[EquipoLocal],V25)+SUMIFS(tPartidos[GV_Real],tPartidos[Jugado],"Sí",tPartidos[EquipoVisita],V25) -> 0 | AB25: =SUMIFS(tPartidos[GV_Real],tPartidos[Jugado],"Sí",tPartidos[EquipoLocal],V25)+SUMIFS(tPartidos[GL_Real],tPartidos[Jugado],"Sí",tPartidos[EquipoVisita],V25) -> 0 | AC25: =AA25-AB25 -> 0 | AD25: =X25*3+Y25 -> 0
B26: Switzerland | C26: 0 | D26: 0 | E26: 0 | F26: 0 | G26: 0 | H26: 0 | I26: 0 | J26: 0 | V26: Switzerland | W26: =COUNTIFS(tPartidos[Jugado],"Sí",tPartidos[EquipoLocal],V26)+COUNTIFS(tPartidos[Jugado],"Sí",tPartidos[EquipoVisita],V26) -> 0 | X26: =SUMPRODUCT((tPartidos[Jugado]="Sí")*(tPartidos[EquipoLocal]=V26)*(tPartidos[GL_Real]>tPartidos[GV_Real]))+SUMPRODUCT((tPartidos[Jugado]="Sí")*(tPartidos[EquipoVisita]=V26)*(tPartidos[GV_Real]>tPartidos[GL_Real])) -> 0 | Y26: =SUMPRODUCT((tPartidos[Jugado]="Sí")*((tPartidos[EquipoLocal]=V26)+(tPartidos[EquipoVisita]=V26))*(tPartidos[GL_Real]=tPartidos[GV_Real])) -> 0 | Z26: =W26-X26-Y26 -> 0 | AA26: =SUMIFS(tPartidos[GL_Real],tPartidos[Jugado],"Sí",tPartidos[EquipoLocal],V26)+SUMIFS(tPartidos[GV_Real],tPartidos[Jugado],"Sí",tPartidos[EquipoVisita],V26) -> 0 | AB26: =SUMIFS(tPartidos[GV_Real],tPartidos[Jugado],"Sí",tPartidos[EquipoLocal],V26)+SUMIFS(tPartidos[GL_Real],tPartidos[Jugado],"Sí",tPartidos[EquipoVisita],V26) -> 0 | AC26: =AA26-AB26 -> 0 | AD26: =X26*3+Y26 -> 0
B28: Grupo C
B29: Equipo | C29: PJ | D29: G | E29: E | F29: P | G29: GF | H29: GC | I29: DG | J29: Pts | K29: Clasifica
B30: {=_xlfn.SORTBY(V30:AD33,AD30:AD33,-1,AC30:AC33,-1,AA30:AA33,-1)} -> Brazil | C30: 0 | D30: 0 | E30: 0 | F30: 0 | G30: 0 | H30: 0 | I30: 0 | J30: 0 | K30: Q | V30: Brazil | W30: =COUNTIFS(tPartidos[Jugado],"Sí",tPartidos[EquipoLocal],V30)+COUNTIFS(tPartidos[Jugado],"Sí",tPartidos[EquipoVisita],V30) -> 0 | X30: =SUMPRODUCT((tPartidos[Jugado]="Sí")*(tPartidos[EquipoLocal]=V30)*(tPartidos[GL_Real]>tPartidos[GV_Real]))+SUMPRODUCT((tPartidos[Jugado]="Sí")*(tPartidos[EquipoVisita]=V30)*(tPartidos[GV_Real]>tPartidos[GL_Real])) -> 0 | Y30: =SUMPRODUCT((tPartidos[Jugado]="Sí")*((tPartidos[EquipoLocal]=V30)+(tPartidos[EquipoVisita]=V30))*(tPartidos[GL_Real]=tPartidos[GV_Real])) -> 0 | Z30: =W30-X30-Y30 -> 0 | AA30: =SUMIFS(tPartidos[GL_Real],tPartidos[Jugado],"Sí",tPartidos[EquipoLocal],V30)+SUMIFS(tPartidos[GV_Real],tPartidos[Jugado],"Sí",tPartidos[EquipoVisita],V30) -> 0 | AB30: =SUMIFS(tPartidos[GV_Real],tPartidos[Jugado],"Sí",tPartidos[EquipoLocal],V30)+SUMIFS(tPartidos[GL_Real],tPartidos[Jugado],"Sí",tPartidos[EquipoVisita],V30) -> 0 | AC30: =AA30-AB30 -> 0 | AD30: =X30*3+Y30 -> 0
B31: Haiti | C31: 0 | D31: 0 | E31: 0 | F31: 0 | G31: 0 | H31: 0 | I31: 0 | J31: 0 | K31: Q | V31: Haiti | W31: =COUNTIFS(tPartidos[Jugado],"Sí",tPartidos[EquipoLocal],V31)+COUNTIFS(tPartidos[Jugado],"Sí",tPartidos[EquipoVisita],V31) -> 0 | X31: =SUMPRODUCT((tPartidos[Jugado]="Sí")*(tPartidos[EquipoLocal]=V31)*(tPartidos[GL_Real]>tPartidos[GV_Real]))+SUMPRODUCT((tPartidos[Jugado]="Sí")*(tPartidos[EquipoVisita]=V31)*(tPartidos[GV_Real]>tPartidos[GL_Real])) -> 0 | Y31: =SUMPRODUCT((tPartidos[Jugado]="Sí")*((tPartidos[EquipoLocal]=V31)+(tPartidos[EquipoVisita]=V31))*(tPartidos[GL_Real]=tPartidos[GV_Real])) -> 0 | Z31: =W31-X31-Y31 -> 0 | AA31: =SUMIFS(tPartidos[GL_Real],tPartidos[Jugado],"Sí",tPartidos[EquipoLocal],V31)+SUMIFS(tPartidos[GV_Real],tPartidos[Jugado],"Sí",tPartidos[EquipoVisita],V31) -> 0 | AB31: =SUMIFS(tPartidos[GV_Real],tPartidos[Jugado],"Sí",tPartidos[EquipoLocal],V31)+SUMIFS(tPartidos[GL_Real],tPartidos[Jugado],"Sí",tPartidos[EquipoVisita],V31) -> 0 | AC31: =AA31-AB31 -> 0 | AD31: =X31*3+Y31 -> 0
B32: Morocco | C32: 0 | D32: 0 | E32: 0 | F32: 0 | G32: 0 | H32: 0 | I32: 0 | J32: 0 | K32: =IF(ISNUMBER(MATCH($B32,$P$16:$P$23,0)),"3°","") -> 3° | V32: Morocco | W32: =COUNTIFS(tPartidos[Jugado],"Sí",tPartidos[EquipoLocal],V32)+COUNTIFS(tPartidos[Jugado],"Sí",tPartidos[EquipoVisita],V32) -> 0 | X32: =SUMPRODUCT((tPartidos[Jugado]="Sí")*(tPartidos[EquipoLocal]=V32)*(tPartidos[GL_Real]>tPartidos[GV_Real]))+SUMPRODUCT((tPartidos[Jugado]="Sí")*(tPartidos[EquipoVisita]=V32)*(tPartidos[GV_Real]>tPartidos[GL_Real])) -> 0 | Y32: =SUMPRODUCT((tPartidos[Jugado]="Sí")*((tPartidos[EquipoLocal]=V32)+(tPartidos[EquipoVisita]=V32))*(tPartidos[GL_Real]=tPartidos[GV_Real])) -> 0 | Z32: =W32-X32-Y32 -> 0 | AA32: =SUMIFS(tPartidos[GL_Real],tPartidos[Jugado],"Sí",tPartidos[EquipoLocal],V32)+SUMIFS(tPartidos[GV_Real],tPartidos[Jugado],"Sí",tPartidos[EquipoVisita],V32) -> 0 | AB32: =SUMIFS(tPartidos[GV_Real],tPartidos[Jugado],"Sí",tPartidos[EquipoLocal],V32)+SUMIFS(tPartidos[GL_Real],tPartidos[Jugado],"Sí",tPartidos[EquipoVisita],V32) -> 0 | AC32: =AA32-AB32 -> 0 | AD32: =X32*3+Y32 -> 0
B33: Scotland | C33: 0 | D33: 0 | E33: 0 | F33: 0 | G33: 0 | H33: 0 | I33: 0 | J33: 0 | V33: Scotland | W33: =COUNTIFS(tPartidos[Jugado],"Sí",tPartidos[EquipoLocal],V33)+COUNTIFS(tPartidos[Jugado],"Sí",tPartidos[EquipoVisita],V33) -> 0 | X33: =SUMPRODUCT((tPartidos[Jugado]="Sí")*(tPartidos[EquipoLocal]=V33)*(tPartidos[GL_Real]>tPartidos[GV_Real]))+SUMPRODUCT((tPartidos[Jugado]="Sí")*(tPartidos[EquipoVisita]=V33)*(tPartidos[GV_Real]>tPartidos[GL_Real])) -> 0 | Y33: =SUMPRODUCT((tPartidos[Jugado]="Sí")*((tPartidos[EquipoLocal]=V33)+(tPartidos[EquipoVisita]=V33))*(tPartidos[GL_Real]=tPartidos[GV_Real])) -> 0 | Z33: =W33-X33-Y33 -> 0 | AA33: =SUMIFS(tPartidos[GL_Real],tPartidos[Jugado],"Sí",tPartidos[EquipoLocal],V33)+SUMIFS(tPartidos[GV_Real],tPartidos[Jugado],"Sí",tPartidos[EquipoVisita],V33) -> 0 | AB33: =SUMIFS(tPartidos[GV_Real],tPartidos[Jugado],"Sí",tPartidos[EquipoLocal],V33)+SUMIFS(tPartidos[GL_Real],tPartidos[Jugado],"Sí",tPartidos[EquipoVisita],V33) -> 0 | AC33: =AA33-AB33 -> 0 | AD33: =X33*3+Y33 -> 0
B35: Grupo D
B36: Equipo | C36: PJ | D36: G | E36: E | F36: P | G36: GF | H36: GC | I36: DG | J36: Pts | K36: Clasifica
B37: {=_xlfn.SORTBY(V37:AD40,AD37:AD40,-1,AC37:AC40,-1,AA37:AA40,-1)} -> Australia | C37: 0 | D37: 0 | E37: 0 | F37: 0 | G37: 0 | H37: 0 | I37: 0 | J37: 0 | K37: Q | V37: Australia | W37: =COUNTIFS(tPartidos[Jugado],"Sí",tPartidos[EquipoLocal],V37)+COUNTIFS(tPartidos[Jugado],"Sí",tPartidos[EquipoVisita],V37) -> 0 | X37: =SUMPRODUCT((tPartidos[Jugado]="Sí")*(tPartidos[EquipoLocal]=V37)*(tPartidos[GL_Real]>tPartidos[GV_Real]))+SUMPRODUCT((tPartidos[Jugado]="Sí")*(tPartidos[EquipoVisita]=V37)*(tPartidos[GV_Real]>tPartidos[GL_Real])) -> 0 | Y37: =SUMPRODUCT((tPartidos[Jugado]="Sí")*((tPartidos[EquipoLocal]=V37)+(tPartidos[EquipoVisita]=V37))*(tPartidos[GL_Real]=tPartidos[GV_Real])) -> 0 | Z37: =W37-X37-Y37 -> 0 | AA37: =SUMIFS(tPartidos[GL_Real],tPartidos[Jugado],"Sí",tPartidos[EquipoLocal],V37)+SUMIFS(tPartidos[GV_Real],tPartidos[Jugado],"Sí",tPartidos[EquipoVisita],V37) -> 0 | AB37: =SUMIFS(tPartidos[GV_Real],tPartidos[Jugado],"Sí",tPartidos[EquipoLocal],V37)+SUMIFS(tPartidos[GL_Real],tPartidos[Jugado],"Sí",tPartidos[EquipoVisita],V37) -> 0 | AC37: =AA37-AB37 -> 0 | AD37: =X37*3+Y37 -> 0
B38: Paraguay | C38: 0 | D38: 0 | E38: 0 | F38: 0 | G38: 0 | H38: 0 | I38: 0 | J38: 0 | K38: Q | V38: Paraguay | W38: =COUNTIFS(tPartidos[Jugado],"Sí",tPartidos[EquipoLocal],V38)+COUNTIFS(tPartidos[Jugado],"Sí",tPartidos[EquipoVisita],V38) -> 0 | X38: =SUMPRODUCT((tPartidos[Jugado]="Sí")*(tPartidos[EquipoLocal]=V38)*(tPartidos[GL_Real]>tPartidos[GV_Real]))+SUMPRODUCT((tPartidos[Jugado]="Sí")*(tPartidos[EquipoVisita]=V38)*(tPartidos[GV_Real]>tPartidos[GL_Real])) -> 0 | Y38: =SUMPRODUCT((tPartidos[Jugado]="Sí")*((tPartidos[EquipoLocal]=V38)+(tPartidos[EquipoVisita]=V38))*(tPartidos[GL_Real]=tPartidos[GV_Real])) -> 0 | Z38: =W38-X38-Y38 -> 0 | AA38: =SUMIFS(tPartidos[GL_Real],tPartidos[Jugado],"Sí",tPartidos[EquipoLocal],V38)+SUMIFS(tPartidos[GV_Real],tPartidos[Jugado],"Sí",tPartidos[EquipoVisita],V38) -> 0 | AB38: =SUMIFS(tPartidos[GV_Real],tPartidos[Jugado],"Sí",tPartidos[EquipoLocal],V38)+SUMIFS(tPartidos[GL_Real],tPartidos[Jugado],"Sí",tPartidos[EquipoVisita],V38) -> 0 | AC38: =AA38-AB38 -> 0 | AD38: =X38*3+Y38 -> 0
B39: Türkiye | C39: 0 | D39: 0 | E39: 0 | F39: 0 | G39: 0 | H39: 0 | I39: 0 | J39: 0 | K39: =IF(ISNUMBER(MATCH($B39,$P$16:$P$23,0)),"3°","") -> 3° | V39: Türkiye | W39: =COUNTIFS(tPartidos[Jugado],"Sí",tPartidos[EquipoLocal],V39)+COUNTIFS(tPartidos[Jugado],"Sí",tPartidos[EquipoVisita],V39) -> 0 | X39: =SUMPRODUCT((tPartidos[Jugado]="Sí")*(tPartidos[EquipoLocal]=V39)*(tPartidos[GL_Real]>tPartidos[GV_Real]))+SUMPRODUCT((tPartidos[Jugado]="Sí")*(tPartidos[EquipoVisita]=V39)*(tPartidos[GV_Real]>tPartidos[GL_Real])) -> 0 | Y39: =SUMPRODUCT((tPartidos[Jugado]="Sí")*((tPartidos[EquipoLocal]=V39)+(tPartidos[EquipoVisita]=V39))*(tPartidos[GL_Real]=tPartidos[GV_Real])) -> 0 | Z39: =W39-X39-Y39 -> 0 | AA39: =SUMIFS(tPartidos[GL_Real],tPartidos[Jugado],"Sí",tPartidos[EquipoLocal],V39)+SUMIFS(tPartidos[GV_Real],tPartidos[Jugado],"Sí",tPartidos[EquipoVisita],V39) -> 0 | AB39: =SUMIFS(tPartidos[GV_Real],tPartidos[Jugado],"Sí",tPartidos[EquipoLocal],V39)+SUMIFS(tPartidos[GL_Real],tPartidos[Jugado],"Sí",tPartidos[EquipoVisita],V39) -> 0 | AC39: =AA39-AB39 -> 0 | AD39: =X39*3+Y39 -> 0
B40: USA | C40: 0 | D40: 0 | E40: 0 | F40: 0 | G40: 0 | H40: 0 | I40: 0 | J40: 0 | V40: USA | W40: =COUNTIFS(tPartidos[Jugado],"Sí",tPartidos[EquipoLocal],V40)+COUNTIFS(tPartidos[Jugado],"Sí",tPartidos[EquipoVisita],V40) -> 0 | X40: =SUMPRODUCT((tPartidos[Jugado]="Sí")*(tPartidos[EquipoLocal]=V40)*(tPartidos[GL_Real]>tPartidos[GV_Real]))+SUMPRODUCT((tPartidos[Jugado]="Sí")*(tPartidos[EquipoVisita]=V40)*(tPartidos[GV_Real]>tPartidos[GL_Real])) -> 0 | Y40: =SUMPRODUCT((tPartidos[Jugado]="Sí")*((tPartidos[EquipoLocal]=V40)+(tPartidos[EquipoVisita]=V40))*(tPartidos[GL_Real]=tPartidos[GV_Real])) -> 0 | Z40: =W40-X40-Y40 -> 0 | AA40: =SUMIFS(tPartidos[GL_Real],tPartidos[Jugado],"Sí",tPartidos[EquipoLocal],V40)+SUMIFS(tPartidos[GV_Real],tPartidos[Jugado],"Sí",tPartidos[EquipoVisita],V40) -> 0 | AB40: =SUMIFS(tPartidos[GV_Real],tPartidos[Jugado],"Sí",tPartidos[EquipoLocal],V40)+SUMIFS(tPartidos[GL_Real],tPartidos[Jugado],"Sí",tPartidos[EquipoVisita],V40) -> 0 | AC40: =AA40-AB40 -> 0 | AD40: =X40*3+Y40 -> 0
B42: Grupo E
B43: Equipo | C43: PJ | D43: G | E43: E | F43: P | G43: GF | H43: GC | I43: DG | J43: Pts | K43: Clasifica
B44: {=_xlfn.SORTBY(V44:AD47,AD44:AD47,-1,AC44:AC47,-1,AA44:AA47,-1)} -> Curaçao | C44: 0 | D44: 0 | E44: 0 | F44: 0 | G44: 0 | H44: 0 | I44: 0 | J44: 0 | K44: Q | V44: Curaçao | W44: =COUNTIFS(tPartidos[Jugado],"Sí",tPartidos[EquipoLocal],V44)+COUNTIFS(tPartidos[Jugado],"Sí",tPartidos[EquipoVisita],V44) -> 0 | X44: =SUMPRODUCT((tPartidos[Jugado]="Sí")*(tPartidos[EquipoLocal]=V44)*(tPartidos[GL_Real]>tPartidos[GV_Real]))+SUMPRODUCT((tPartidos[Jugado]="Sí")*(tPartidos[EquipoVisita]=V44)*(tPartidos[GV_Real]>tPartidos[GL_Real])) -> 0 | Y44: =SUMPRODUCT((tPartidos[Jugado]="Sí")*((tPartidos[EquipoLocal]=V44)+(tPartidos[EquipoVisita]=V44))*(tPartidos[GL_Real]=tPartidos[GV_Real])) -> 0 | Z44: =W44-X44-Y44 -> 0 | AA44: =SUMIFS(tPartidos[GL_Real],tPartidos[Jugado],"Sí",tPartidos[EquipoLocal],V44)+SUMIFS(tPartidos[GV_Real],tPartidos[Jugado],"Sí",tPartidos[EquipoVisita],V44) -> 0 | AB44: =SUMIFS(tPartidos[GV_Real],tPartidos[Jugado],"Sí",tPartidos[EquipoLocal],V44)+SUMIFS(tPartidos[GL_Real],tPartidos[Jugado],"Sí",tPartidos[EquipoVisita],V44) -> 0 | AC44: =AA44-AB44 -> 0 | AD44: =X44*3+Y44 -> 0
B45: Ecuador | C45: 0 | D45: 0 | E45: 0 | F45: 0 | G45: 0 | H45: 0 | I45: 0 | J45: 0 | K45: Q | V45: Ecuador | W45: =COUNTIFS(tPartidos[Jugado],"Sí",tPartidos[EquipoLocal],V45)+COUNTIFS(tPartidos[Jugado],"Sí",tPartidos[EquipoVisita],V45) -> 0 | X45: =SUMPRODUCT((tPartidos[Jugado]="Sí")*(tPartidos[EquipoLocal]=V45)*(tPartidos[GL_Real]>tPartidos[GV_Real]))+SUMPRODUCT((tPartidos[Jugado]="Sí")*(tPartidos[EquipoVisita]=V45)*(tPartidos[GV_Real]>tPartidos[GL_Real])) -> 0 | Y45: =SUMPRODUCT((tPartidos[Jugado]="Sí")*((tPartidos[EquipoLocal]=V45)+(tPartidos[EquipoVisita]=V45))*(tPartidos[GL_Real]=tPartidos[GV_Real])) -> 0 | Z45: =W45-X45-Y45 -> 0 | AA45: =SUMIFS(tPartidos[GL_Real],tPartidos[Jugado],"Sí",tPartidos[EquipoLocal],V45)+SUMIFS(tPartidos[GV_Real],tPartidos[Jugado],"Sí",tPartidos[EquipoVisita],V45) -> 0 | AB45: =SUMIFS(tPartidos[GV_Real],tPartidos[Jugado],"Sí",tPartidos[EquipoLocal],V45)+SUMIFS(tPartidos[GL_Real],tPartidos[Jugado],"Sí",tPartidos[EquipoVisita],V45) -> 0 | AC45: =AA45-AB45 -> 0 | AD45: =X45*3+Y45 -> 0
...

Sheet DASHBOARD
D3: Dashboard – Mundial 2026 (Fase de Grupos)
A5: Participantes y puntos | D5: Avance de la fase de grupos
A6: Participante | B6: Puntos | C6: Top 10 | F6: Jugados | H6: Pendientes | J6: % avance | BD6: Estado | BE6: Cantidad
C7: Participante | D7: Puntos | F7: =COUNTIF(tPartidos[Jugado],"Sí") -> 0 | H7: =72-F7 -> 72 | J7: =IFERROR(F7/72,0) -> 0 | BD7: Jugados | BE7: =F7 -> 0
BD8: Pendientes | BE8: =H7 -> 72
D9: Avance por grupo
D10: Grupo | E10: Jugados | F10: Pendientes | G10: % | BD10: Tipo | BE10: Cantidad
D11: A | E11: =COUNTIFS(tPartidos[Grupo],"A",tPartidos[Jugado],"Sí") -> 0 | F11: =6-E11 -> 6 | G11: =IFERROR(E11/6,0) -> 0 | BD11: Directos (Top 2) | BE11: 24
D12: B | E12: =COUNTIFS(tPartidos[Grupo],"B",tPartidos[Jugado],"Sí") -> 0 | F12: =6-E12 -> 6 | G12: =IFERROR(E12/6,0) -> 0 | BD12: Mejores terceros | BE12: 8
D13: C | E13: =COUNTIFS(tPartidos[Grupo],"C",tPartidos[Jugado],"Sí") -> 0 | F13: =6-E13 -> 6 | G13: =IFERROR(E13/6,0) -> 0
D14: D | E14: =COUNTIFS(tPartidos[Grupo],"D",tPartidos[Jugado],"Sí") -> 0 | F14: =6-E14 -> 6 | G14: =IFERROR(E14/6,0) -> 0
D15: E | E15: =COUNTIFS(tPartidos[Grupo],"E",tPartidos[Jugado],"Sí") -> 0 | F15: =6-E15 -> 6 | G15: =IFERROR(E15/6,0) -> 0
D16: F | E16: =COUNTIFS(tPartidos[Grupo],"F",tPartidos[Jugado],"Sí") -> 0 | F16: =6-E16 -> 6 | G16: =IFERROR(E16/6,0) -> 0
D17: G | E17: =COUNTIFS(tPartidos[Grupo],"G",tPartidos[Jugado],"Sí") -> 0 | F17: =6-E17 -> 6 | G17: =IFERROR(E17/6,0) -> 0
D18: H | E18: =COUNTIFS(tPartidos[Grupo],"H",tPartidos[Jugado],"Sí") -> 0 | F18: =6-E18 -> 6 | G18: =IFERROR(E18/6,0) -> 0
D19: I | E19: =COUNTIFS(tPartidos[Grupo],"I",tPartidos[Jugado],"Sí") -> 0 | F19: =6-E19 -> 6 | G19: =IFERROR(E19/6,0) -> 0
D20: J | E20: =COUNTIFS(tPartidos[Grupo],"J",tPartidos[Jugado],"Sí") -> 0 | F20: =6-E20 -> 6 | G20: =IFERROR(E20/6,0) -> 0
D21: K | E21: =COUNTIFS(tPartidos[Grupo],"K",tPartidos[Jugado],"Sí") -> 0 | F21: =6-E21 -> 6 | G21: =IFERROR(E21/6,0) -> 0
D22: L | E22: =COUNTIFS(tPartidos[Grupo],"L",tPartidos[Jugado],"Sí") -> 0 | F22: =6-E22 -> 6 | G22: =IFERROR(E22/6,0) -> 0 | BD22: Participante | BE22: Puntos
BD23: {=_xlfn.TAKE(_xlfn.SORTBY(_xlfn._xlws.FILTER(TABLA_GENERAL!B8:C57,TABLA_GENERAL!B8:B57<>""),INDEX(_xlfn._xlws.FILTER(TABLA_GENERAL!B8:C57,TABLA_GENERAL!B8:B57<>""),,2),-1),10)} -> Jugador 1 | BE23: 0
BD24: Jugador 2 | BE24: 0
D25: Clasificados directos (1° y 2° de cada grupo) | BD25: Jugador 3 | BE25: 0
D26: Grupo | E26: 1° | F26: 2° | BD26: Jugador 4 | BE26: 0
D27: A | E27: =POSICIONES!$B$16 -> Czechia | F27: =POSICIONES!$B$17 -> Mexico | BD27: Jugador 5 | BE27: 0
D28: B | E28: =POSICIONES!$B$23 -> Bosnia & Herzegovina | F28: =POSICIONES!$B$24 -> Canada | BD28: Jugador 6 | BE28: 0
D29: C | E29: =POSICIONES!$B$30 -> Brazil | F29: =POSICIONES!$B$31 -> Haiti | BD29: Jugador 7 | BE29: 0
D30: D | E30: =POSICIONES!$B$37 -> Australia | F30: =POSICIONES!$B$38 -> Paraguay | BD30: Jugador 8 | BE30: 0
D31: E | E31: =POSICIONES!$B$44 -> Curaçao | F31: =POSICIONES!$B$45 -> Ecuador | BD31: Jugador 9 | BE31: 0
D32: F | E32: =POSICIONES!$B$51 -> Japan | F32: =POSICIONES!$B$52 -> Netherlands | BD32: Jugador 10 | BE32: 0
D33: G | E33: =POSICIONES!$B$58 -> Belgium | F33: =POSICIONES!$B$59 -> Egypt
D34: H | E34: =POSICIONES!$B$65 -> Cape Verde | F34: =POSICIONES!$B$66 -> Saudi Arabia
D35: I | E35: =POSICIONES!$B$72 -> France | F35: =POSICIONES!$B$73 -> Iraq
D36: J | E36: =POSICIONES!$B$79 -> Algeria | F36: =POSICIONES!$B$80 -> Argentina
D37: K | E37: =POSICIONES!$B$86 -> Colombia | F37: =POSICIONES!$B$87 -> DR Congo
D38: L | E38: =POSICIONES!$B$93 -> Croatia | F38: =POSICIONES!$B$94 -> England
D42: Mejores terceros (Top 8)
D43: Pos | E43: Grupo | F43: Equipo | G43: Pts | H43: DG | I43: GF
D44: 1 | E44: =POSICIONES!$O$16 -> A | F44: =POSICIONES!$P$16 -> South Africa | G44: =POSICIONES!$Q$16 -> 0 | H44: =POSICIONES!$R$16 -> 0 | I44: =POSICIONES!$S$16 -> 0
D45: 2 | E45: =POSICIONES!$O$17 -> B | F45: =POSICIONES!$P$17 -> Qatar | G45: =POSICIONES!$Q$17 -> 0 | H45: =POSICIONES!$R$17 -> 0 | I45: =POSICIONES!$S$17 -> 0
D46: 3 | E46: =POSICIONES!$O$18 -> C | F46: =POSICIONES!$P$18 -> Morocco | G46: =POSICIONES!$Q$18 -> 0 | H46: =POSICIONES!$R$18 -> 0 | I46: =POSICIONES!$S$18 -> 0
...
